Workbook

Sheet Лист1
A1: Период | B1: Выручка | C1: Прямые операционные расходы МДО (без разработки) | D1: Разработка МДО в штате | E1: Сдельная оплата по разрботке МДО | F1: Операционные расходы МДО всего | G1: Аллокация / услуги ГК | H1: Операционный результат до разовых выплат | I1: Выплаты учредителям | J1: Выплаты ООО «66 Бит» | K1: Выплаты по отдельным проектам разработки | L1: Всего расходов и выплат | M1: Денежный результат после всех выплат
A2: Окт-25 | B2: =4046953 -> 4046953 | C2: =704273.25 -> 704273.25 | D2: =580000 -> 580000 | E2: =2031 -> 2031 | F2: =C2+D2+E2 -> 1286304.2 | G2: =3956 -> 3956 | H2: =B2-(F2+G2) -> 2756692.8 | I2: 0 | J2: 0 | K2: 0 | L2: =F2+G2+I2+J2+K2 -> 1290260.2 | M2: =B2-L2 -> 2756692.8
A3: Ноя-25 | B3: =2993464 -> 2993464 | C3: =919146.64 -> 919146.64 | D3: =580000 -> 580000 | E3: =77228 -> 77228 | F3: =C3+D3+E3 -> 1576374.6 | G3: =57958 -> 57958 | H3: =B3-(F3+G3) -> 1359131.4 | I3: 0 | J3: 0 | K3: 0 | L3: =F3+G3+I3+J3+K3 -> 1634332.6 | M3: =B3-L3 -> 1359131.4
A4: Дек-25 | B4: =3227370 -> 3227370 | C4: =1014219.16 -> 1014219.2 | D4: =580000 -> 580000 | E4: 119522 | F4: =C4+D4+E4 -> 1713741.2 | G4: =6450 -> 6450 | H4: =B4-(F4+G4) -> 1507178.8 | I4: =6035451.01 -> 6035451 | J4: 0 | K4: 0 | L4: =F4+G4+I4+J4+K4 -> 7755642.2 | M4: =B4-L4 -> -4528272.2
A5: Янв-26 | B5: =2187345 -> 2187345 | C5: =673585.69 -> 673585.69 | D5: =580000 -> 580000 | E5: 177737 | F5: =C5+D5+E5 -> 1431322.7 | G5: 0 | H5: =B5-(F5+G5) -> 756022.31 | I5: 0 | J5: =594560.45 -> 594560.45 | K5: 0 | L5: =F5+G5+I5+J5+K5 -> 2025883.1 | M5: =B5-L5 -> 161461.86
A6: Фев-26 | B6: =3223366 -> 3223366 | C6: =363096.5 -> 363096.5 | D6: =580000 -> 580000 | E6: 159710 | F6: =C6+D6+E6 -> 1102806.5 | G6: =2400 -> 2400 | H6: =B6-(F6+G6) -> 2118159.5 | I6: 0 | J6: 0 | K6: 0 | L6: =F6+G6+I6+J6+K6 -> 1105206.5 | M6: =B6-L6 -> 2118159.5
A7: Мар-26 | B7: =2282189.63 -> 2282189.6 | C7: =1056685.13 -> 1056685.1 | D7: =580000 -> 580000 | E7: 125355 | F7: =C7+D7+E7 -> 1762040.1 | G7: =2804.77 -> 2804.77 | H7: =B7-(F7+G7) -> 517344.73 | I7: 0 | J7: 0 | K7: 0 | L7: =F7+G7+I7+J7+K7 -> 1764844.9 | M7: =B7-L7 -> 517344.73
A8: Апр-26 | B8: =1194624.2 -> 1194624.2 | C8: =SUMIFS('Детализация_июнь'!$I$2:$I$79,'Детализация_июнь'!$A$2:$A$79,"Апр-26",'Детализация_июнь'!$J$2:$J$79,"Опер. расходы МДО без разработки",'Детализация_июнь'!$K$2:$K$79,"Да") -> 830333.48 | D8: =450000 -> 450000 | E8: 151200 | F8: =C8+D8+E8 -> 1431533.5 | G8: =30060 -> 30060 | H8: =B8-(F8+G8) -> -266969.28 | I8: 0 | J8: =594560.45 -> 594560.45 | K8: 0 | L8: =F8+G8+I8+J8+K8 -> 2056153.9 | M8: =B8-L8 -> -861529.73
A9: Май-26 | B9: =2372400.5 -> 2372400.5 | C9: =SUMIFS('Детализация_июнь'!$I$2:$I$79,'Детализация_июнь'!$A$2:$A$79,"Май-26",'Детализация_июнь'!$J$2:$J$79,"Опер. расходы МДО без разработки",'Детализация_июнь'!$K$2:$K$79,"Да") -> 5719509.2 | D9: =450000 -> 450000 | E9: 127495 | F9: =C9+D9+E9 -> 6297004.2 | G9: =17500 -> 17500 | H9: =B9-(F9+G9) -> -3942103.7 | I9: 0 | J9: 0 | K9: =3997297 -> 3997297 | L9: =F9+G9+I9+J9+K9 -> 10311801 | M9: =B9-L9 -> -7939400.7
A10: Июн-26 | B10: =SUMIFS('Детализация_июнь'!$I$2:$I$79,'Детализация_июнь'!$A$2:$A$79,"Июнь-26",'Детализация_июнь'!$J$2:$J$79,"Выручка",'Детализация_июнь'!$K$2:$K$79,"Да") -> 2750662 | C10: =SUMIFS('Детализация_июнь'!$I$2:$I$79,'Детализация_июнь'!$A$2:$A$79,"Июнь-26",'Детализация_июнь'!$J$2:$J$79,"Опер. расходы МДО без разработки",'Детализация_июнь'!$K$2:$K$79,"Да") -> 241414 | D10: =450000 -> 450000 | E10: 72470 | F10: =C10+D10+E10 -> 763884 | G10: =SUMIFS('Детализация_июнь'!$I$2:$I$79,'Детализация_июнь'!$A$2:$A$79,"Июнь-26",'Детализация_июнь'!$J$2:$J$79,"Аллокация ГК",'Детализация_июнь'!$K$2:$K$79,"Да") -> 34337.48 | H10: =B10-(F10+G10) -> 1952440.5 | I10: =SUMIFS('Детализация_июнь'!$I$2:$I$79,'Детализация_июнь'!$A$2:$A$79,"Июнь-26",'Детализация_июнь'!$J$2:$J$79,"Выплаты учредителям",'Детализация_июнь'!$K$2:$K$79,"Да") -> 0 | J10: =SUMIFS('Детализация_июнь'!$I$2:$I$79,'Детализация_июнь'!$A$2:$A$79,"Июнь-26",'Детализация_июнь'!$J$2:$J$79,"66bit",'Детализация_июнь'!$K$2:$K$79,"Да") -> 1189120.9 | K10: =SUMIFS('Детализация_июнь'!$I$2:$I$79,'Детализация_июнь'!$A$2:$A$79,"Июнь-26",'Детализация_июнь'!$J$2:$J$79,"Инвест. разработка прочая",'Детализация_июнь'!$K$2:$K$79,"Да") -> 0 | L10: =F10+G10+I10+J10+K10 -> 1987342.4 | M10: =B10-L10 -> 763319.61
A11: Итого | B11: =SUM(B2:B10) -> 24278374 | C11: =SUM(C2:C10) -> 11522263 | D11: =SUM(D2:D10) -> 4830000 | E11: =SUM(E2:E10) -> 1012748 | F11: =C11+D11+E11 -> 17365011 | G11: =SUM(G2:G10) -> 155466.25 | H11: =SUM(H2:H10) -> 6757897.1 | I11: =SUM(I2:I10) -> 6035451 | J11: =SUM(J2:J10) -> 2378241.8 | K11: =SUM(K2:K10) -> 3997297 | L11: =SUM(L2:L10) -> 29931467 | M11: =SUM(M2:M10) -> -5653092.8

Sheet Детализация_июнь
A1: Период учета | B1: Источник | C1: Строка | D1: Дата платежа | E1: Месяц начисления | F1: Контрагент | G1: Статья CF | H1: Содержание | I1: Сумма, ₽ | J1: Категория сводки | K1: Включить | L1: Статус / примечание | M1: Назначение платежа / ссылка
A2: Апр-26 | B2: Аллокация с ГК (исходная база) | C2: C8 | E2: Апрель | G2: Согласованная база | H2: Опер. расходы МДО без разработки до позднего закрытия | I2: 805271.34 | J2: Опер. расходы МДО без разработки | K2: Да | L2: Сохраненная база исходного файла
A3: Май-26 | B3: Аллокация с ГК (исходная база) | C3: C9 | E3: Май | G3: Согласованная база | H3: Опер. расходы МДО без разработки до позднего закрытия | I3: 5048738.4 | J3: Опер. расходы МДО без разработки | K3: Да | L3: Сохраненная база исходного файла
A4: Июнь-26 | B4: Аллокация с ГК (исходный ручной ввод) | C4: D10 | E4: Июнь | G4: Разработка МДО | H4: Значение было в исходной таблице до обработки июньских CF | I4: 1162905 | J4: Разработка МДО | K4: Да | L4: Отдельный управленческий ввод владельца модели: зарплаты разработчиков не отражены в CF и добавляются сверх CF-расходов
A5: Июнь-26 | B5: МДО - Мега-таблица | C5: Аккаунты!W70 | E5: Июнь | G5: Факт отдела на р/с | H5: Выручка за июнь 2026 | I5: 2750662 | J5: Выручка | K5: Да | L5: Read-only источник; прочитано 2026-07-15 | M5: https://docs.google.com/spreadsheets/d/1bXWqqMn_WEX1mROcWW6VJw00v4iohmZCQ22nI9gUI9M/edit#gid=1404717816
A6: Май-26 | B6: 57_ЖКХ, CF за июнь 2026 | C6: 3 | D6: 05.06.2026 | E6: Май | F6: Сырица Богдан Альбертович | G6: Зарплата сотрудников проекта | H6: Сырица Б/ЗП за май 2026 (ГПХ) | I6: 51949.99 | J6: Опер. расходы МДО без разработки | K6: Да | L6: Прямой расход МДО
A7: Май-26 | B7: 57_ЖКХ, CF за июнь 2026 | C7: 4 | D7: 05.06.2026 | E7: Май | F7: Киви АО | G7: Услуги банка | H7: Сырица Б/ЗП за май 2026 (ГПХ) | I7: 325.87 | J7: Опер. расходы МДО без разработки | K7: Да | L7: Прямой расход МДО
A8: Май-26 | B8: 57_ЖКХ, CF за июнь 2026 | C8: 5 | D8: 05.06.2026 | E8: Май | F8: Шевцов Александр Михайлович | G8: Зарплата сотрудников проекта | H8: Шевцов А/ЗП за май 2026 (ГПХ) | I8: 57500 | J8: Опер. расходы МДО без разработки | K8: Да | L8: Прямой расход МДО
A9: Май-26 | B9: 57_ЖКХ, CF за июнь 2026 | C9: 6 | D9: 05.06.2026 | E9: Май | F9: Кухарь Ксения Александровна | G9: Зарплата сотрудников проекта | H9: Кухарь К/ЗП за май 2026 (СМЗ) | I9: 40000 | J9: Опер. расходы МДО без разработки | K9: Да | L9: Прямой расход МДО
A10: Май-26 | B10: 57_ЖКХ, CF за июнь 2026 | C10: 7 | D10: 05.06.2026 | E10: Май | F10: Кухарь Ксения Александровна | G10: НДФЛ, НПД с з/п сотрудников проекта | H10: Кухарь К/ЗП за май 2026 (СМЗ) | I10: 2553.19 | J10: Опер. расходы МДО без разработки | K10: Да | L10: Прямой расход МДО
A11: Май-26 | B11: 57_ЖКХ, CF за июнь 2026 | C11: 8 | D11: 05.06.2026 | E11: Май | F11: Простые решения ООО | G11: Услуги банка | H11: Кухарь К/ЗП за май 2026 (СМЗ) | I11: 553.19 | J11: Опер. расходы МДО без разработки | K11: Да | L11: Прямой расход МДО
A12: Май-26 | B12: 57_ЖКХ, CF за июнь 2026 | C12: 9 | D12: 05.06.2026 | E12: Май | F12: Коробейников Алексей Станиславович | G12: Зарплата сотрудников проекта | H12: Коробейников А/ЗП за май 2026 (СМЗ) | I12: 57500 | J12: Опер. расходы МДО без разработки | K12: Да | L12: Прямой расход МДО
A13: Май-26 | B13: 57_ЖКХ, CF за июнь 2026 | C13: 10 | D13: 05.06.2026 | E13: Май | F13: Коробейников Алексей Станиславович | G13: НДФЛ, НПД с з/п сотрудников проекта | H13: Коробейников А/ЗП за май 2026 (СМЗ) | I13: 3670.21 | J13: Опер. расходы МДО без разработки | K13: Да | L13: Прямой расход МДО
A14: Май-26 | B14: 57_ЖКХ, CF за июнь 2026 | C14: 11 | D14: 05.06.2026 | E14: Май | F14: Простые решения ООО | G14: Услуги банка | H14: Коробейников А/ЗП за май 2026 (СМЗ) | I14: 795.21 | J14: Опер. расходы МДО без разработки | K14: Да | L14: Прямой расход МДО
A15: Май-26 | B15: 57_ЖКХ, CF за июнь 2026 | C15: 12 | D15: 08.06.2026 | E15: Май | F15: Медунова (Костюкевич) Юлия Ильинична | G15: Премии и бонусы сотрудникам ГК | H15: Медунова (Костюкевич) Ю.И. / Бонус за май 2026 г. (ГПХ) | I15: 43088.44 | J15: Опер. расходы МДО без разработки | K15: Да | L15: Прямой расход МДО
A16: Май-26 | B16: 57_ЖКХ, CF за июнь 2026 | C16: 13 | D16: 08.06.2026 | E16: Май | F16: Киви АО | G16: Услуги банка | H16: Медунова (Костюкевич) Ю.И. / Бонус за май 2026 г. (ГПХ) | I16: 321.7 | J16: Опер. расходы МДО без разработки | K16: Да | L16: Прямой расход МДО
A17: Июнь-26 | B17: 57_ЖКХ, CF за июнь 2026 | C17: 14 | D17: 08.06.2026 | E17: Июнь | F17: ПАО СБЕРБАНК | G17: Услуги банка | I17: 199 | J17: Опер. расходы МДО без разработки | K17: Да | L17: Прямой расход МДО | M17: Комиссия за услугу "Информирование о поступлении и списании средств по банковским счетам в валюте РФ" за период с 08.06.2026 по 08.07.2026 по договору от 29.08.2019 № 243275547
A18: Июнь-26 | B18: 57_ЖКХ, CF за июнь 2026 | C18: 15 | D18: 08.06.2026 | E18: Июнь | F18: ПАО СБЕРБАНК | G18: Услуги банка | I18: 398 | J18: Опер. расходы МДО без разработки | K18: Да | L18: Прямой расход МДО | M18: Комиссия за услугу "Информирование о поступлении и списании средств по банковским счетам в валюте РФ" за период с 08.06.2026 по 08.07.2026 по договору от 29.08.2019 № 243275547
A19: Май-26 | B19: 57_ЖКХ, CF за июнь 2026 | C19: 16 | D19: 09.06.2026 | E19: Май | F19: Скоробогатов (1) Андрей Владимирович | G19: Зарплата сотрудников проекта | H19: Скоробогатов А/ЗП за май 2026 (СМЗ) | I19: 65550 | J19: Опер. расходы МДО без разработки | K19: Да | L19: Прямой расход МДО
A20: Май-26 | B20: 57_ЖКХ, CF за июнь 2026 | C20: 17 | D20: 09.06.2026 | E20: Май | F20: Скоробогатов (1) Андрей Владимирович | G20: НДФЛ, НПД с з/п сотрудников проекта | H20: Скоробогатов А/ЗП за май 2026 (СМЗ) | I20: 4184.04 | J20: Опер. расходы МДО без разработки | K20: Да | L20: Прямой расход МДО
A21: Май-26 | B21: 57_ЖКХ, CF за июнь 2026 | C21: 18 | D21: 09.06.2026 | E21: Май | F21: Простые решения ООО | G21: Услуги банка | H21: Скоробогатов А/ЗП за май 2026 (СМЗ) | I21: 906.54 | J21: Опер. расходы МДО без разработки | K21: Да | L21: Прямой расход МДО
A22: Май-26 | B22: 57_ЖКХ, CF за июнь 2026 | C22: 19 | D22: 09.06.2026 | E22: Май | F22: Амосов Станислав Владимирович | G22: Зарплата сотрудников проекта | H22: Амосов С/ЗП за май 2026 1 часть (СМЗ) | I22: 75000 | J22: Опер. расходы МДО без разработки | K22: Да | L22: Прямой расход МДО
A23: Май-26 | B23: 57_ЖКХ, CF за июнь 2026 | C23: 20 | D23: 09.06.2026 | E23: Май | F23: Амосов Станислав Владимирович | G23: НДФЛ, НПД с з/п сотрудников проекта | H23: Амосов С/ЗП за май 2026 1 часть (СМЗ) | I23: 4787.23 | J23: Опер. расходы МДО без разработки | K23: Да | L23: Прямой расход МДО
A24: Май-26 | B24: 57_ЖКХ, CF за июнь 2026 | C24: 21 | D24: 09.06.2026 | E24: Май | F24: Простые решения ООО | G24: Услуги банка | H24: Амосов С/ЗП за май 2026 1 часть (СМЗ) | I24: 1037.23 | J24: Опер. расходы МДО без разработки | K24: Да | L24: Прямой расход МДО
A25: Май-26 | B25: 57_ЖКХ, CF за июнь 2026 | C25: 22 | D25: 10.06.2026 | E25: Май | F25: Сайдулин Леонид Игоревич | G25: Зарплата сотрудников проекта | H25: Сайдулин Р/ЗП за май 2026 (СМЗ) | I25: 90000 | J25: Опер. расходы МДО без разработки | K25: Да | L25: Прямой расход МДО
A26: Май-26 | B26: 57_ЖКХ, CF за июнь 2026 | C26: 23 | D26: 10.06.2026 | E26: Май | F26: Сайдулин Леонид Игоревич | G26: НДФЛ, НПД с з/п сотрудников проекта | H26: Сайдулин Р/ЗП за май 2026 (СМЗ) | I26: 5744.68 | J26: Опер. расходы МДО без разработки | K26: Да | L26: Прямой расход МДО
A27: Май-26 | B27: 57_ЖКХ, CF за июнь 2026 | C27: 24 | D27: 10.06.2026 | E27: Май | F27: Простые решения ООО | G27: Услуги банка | H27: Сайдулин Р/ЗП за май 2026 (СМЗ) | I27: 1244.68 | J27: Опер. расходы МДО без разработки | K27: Да | L27: Прямой расход МДО
A28: Май-26 | B28: 57_ЖКХ, CF за июнь 2026 | C28: 25 | D28: 10.06.2026 | E28: Май | F28: Амосов Станислав Владимирович | G28: Зарплата сотрудников проекта | H28: Амосов С/ЗП за май 2026 2 часть (СМЗ) | I28: 75000 | J28: Опер. расходы МДО без разработки | K28: Да | L28: Прямой расход МДО
A29: Май-26 | B29: 57_ЖКХ, CF за июнь 2026 | C29: 26 | D29: 10.06.2026 | E29: Май | F29: Амосов Станислав Владимирович | G29: НДФЛ, НПД с з/п сотрудников проекта | H29: Амосов С/ЗП за май 2026 2 часть (СМЗ) | I29: 4787.23 | J29: Опер. расходы МДО без разработки | K29: Да | L29: Прямой расход МДО
A30: Май-26 | B30: 57_ЖКХ, CF за июнь 2026 | C30: 27 | D30: 10.06.2026 | E30: Май | F30: Простые решения ООО | G30: Услуги банка | H30: Амосов С/ЗП за май 2026 2 часть (СМЗ) | I30: 1037.23 | J30: Опер. расходы МДО без разработки | K30: Да | L30: Прямой расход МДО
... A49: Июнь-26 | B49: 57_ЖКХ, CF за июнь 2026 | C49: 46 | D49: 30.06.2026 | E49: Июнь | F49: Электронные сервисы Маркетинга | G49: Вспомогат. ресурсы для продвижения | H49: Распределение/ Расходы seo/ Topvisor/ июнь 2026 | I49: 157.48 | J49: Аллокация ГК | K49: Да | L49: Распределенный расход ГК, отнесенный на МДО
A50: Июнь-26 | B50: 57_ЖКХ, CF за июнь 2026 | C50: 47 | D50: 30.06.2026 | E50: Июнь | F50: ООО «ЛайфТелеком» | G50: Оплата поставщику за товары, работы, услуги | H50: Мой Дом Онлайн/ Оплата за ВАТС Телфин | I50: 50000 | J50: Опер. расходы МДО без разработки | K50: Да | L50: Включено по месяцу начисления июнь; назначение содержит предоплату, нужен контроль акта/остатка | M50: Внесение предоплаты "WOE59270" по счету WOE59270/2506 от 25.06.2026 г. Сумма 50000-00 В т.ч. НДС(22%) 9016-39 ID:f51316b5-745b-11f1-af1c-005056955331
A51: Июнь-26 | B51: 98_Забаланс, CF за июнь 2026 | C51: 11 | D51: 01.06.2026 | E51: Июнь | F51: ПАО СБЕРБАНК | G51: Услуги банка | I51: 700 | J51: Опер. расходы МДО без разработки | K51: Да | L51: Прямой расход МДО | M51: Комиссия за перечисление средств со счета в валюте РФ в другие банки (кредитные организации, Банк России) по системе БЭСП. Без НДС. Договор РКО №40702810716540062640 от 28.08.2019
A52: Июнь-26 | B52: 98_Забаланс, CF за июнь 2026 | C52: 12 | D52: 01.06.2026 | E52: Июнь | F52: СМАРТФ, ООО | G52: ВКО между р/с | I52: 9871.69 | J52: Исключено из P&L | K52: Нет | L52: ВКО / внутренний перевод; не является расходом P&L
A53: Июнь-26 | B53: 98_Забаланс, CF за июнь 2026 | C53: 13 | D53: 01.06.2026 | E53: Июнь | F53: Городская реклама ООО | G53: ВКО между МХ | I53: 1477811 | J53: Исключено из P&L | K53: Нет | L53: ВКО / внутренний перевод; не является расходом P&L | M53: Оплата за услуги колл-центра и сопровождения клиентов по счету №110 от 29.05.2026г. НДС не облагается.
A54: Июнь-26 | B54: 98_Забаланс, CF за июнь 2026 | C54: 14 | D54: 01.06.2026 | E54: Июнь | F54: Бренд Лаборатория ООО | G54: ВКО между МХ | I54: 1485137 | J54: Исключено из P&L | K54: Нет | L54: ВКО / внутренний перевод; не является расходом P&L | M54: Оплата за доработку программного модуля "Система мониторинга и анализа эксплуатации МКД" по счету № 79 от 29.05.2026г. НДС не облагается.
A55: Май-26 | B55: 98_Забаланс, CF за июнь 2026 | C55: 15 | D55: 01.06.2026 | E55: Май | F55: claude.ai | G55: Программное обеспечение | H55: Саитов Д./Возмещение за оплату Claude-AI/ май 2026 | I55: 1349 | J55: Опер. расходы МДО без разработки | K55: Да | L55: Прямой расход МДО
A56: Июнь-26 | B56: 98_Забаланс, CF за июнь 2026 | C56: 16 | D56: 01.06.2026 | E56: Июнь | F56: claude.ai | G56: Программное обеспечение | H56: Мотусков К./Возмещение за оплату Claude-AI/ июнь 2026 | I56: 8522.69 | J56: Опер. расходы МДО без разработки | K56: Да | L56: Прямой расход МДО
A57: Июнь-26 | B57: 98_Забаланс, CF за июнь 2026 | C57: 19 | D57: 03.06.2026 | E57: Июнь | F57: ЯНДЕКС.ОБЛАКО | G57: Оплата поставщику за товары, работы, услуги | H57: Мой Дом Онлайн/Яндекс.Облако/06.26 | I57: 25000 | J57: Опер. расходы МДО без разработки | K57: Да | L57: Прямой расход МДО | M57: Оплата за услуги использования сервисов платформы "Яндекс.Облако" по лицевому счету № ЛСО-3379672502-1 от 01.06.2026г. Сумма 25000-00 В т.ч. НДС(22%) 4508-20 ID:42e713bf-5f19-11f1-aedf-005056955331
A58: Июнь-26 | B58: 98_Забаланс, CF за июнь 2026 | C58: 21 | D58: 05.06.2026 | E58: Июнь | F58: claude.ai | G58: Программное обеспечение | H58: Корсунова А./Возмещение за оплату Claude-AI/ июнь 2026 | I58: 1576.65 | J58: Опер. расходы МДО без разработки | K58: Да | L58: Прямой расход МДО | M58: Компенсации по реестру №19 от 05.06.2026 в соответствии с Договором 83360577 от 29.10.2024
...

Sheet Проверки
A1: Проверка | B1: Значение | C1: Статус | D1: Комментарий
A2: Обычный CF: детализация | B2: 749172.86 | C2: PASS | D2: Сумма всех расходных операций, без строки ВСЕГО
A3: Обычный CF: итог отчета | B3: 749172.86 | C3: PASS | D3: CF, общий итог
A4: Обычный CF: разница | B4: 0 | C4: PASS | D4: Детализация минус итог
A5: Забаланс: детализация | B5: 7430140.1 | C5: PASS | D5: Сумма всех расходных операций, без строки ВСЕГО
A6: Забаланс: итог отчета | B6: 7430140.1 | C6: PASS | D6: CF, общий итог
A7: Забаланс: ВКО исключено | B7: 6018607.7 | C7: PASS | D7: ВКО между МХ и р/с не включено в P&L
A8: Забаланс: после ВКО | B8: 1411532.4 | C8: PASS | D8: Операционные + инвестиционные расходы
A9: Забаланс: операционные + 66bit | B9: 1411532.4 | C9: PASS | D9: 222 411,53 + 1 189 120,91
A10: Позднее закрытие апреля | B10: 25062.14 | C10: PASS | D10: Отнесено в Апр-26
A11: Позднее закрытие мая | B11: 670770.77 | C11: PASS | D11: Отнесено в Май-26
A12: Июнь: прямые OPEX МДО | B12: 241414 | C12: PASS | D12: Без разработки и без аллокации
A13: Июнь: аллокация ГК | B13: 34337.48 | C13: PASS | D13: HeadHunter, Roistat, Coldy, Topvisor
... A15: Июнь: разработка МДО | B15: 1162905 | C15: MANUAL | D15: Отдельный управленческий ввод владельца модели; отсутствие суммы в CF не является расхождением

Sheet Методология
A1: Показатель | B1: Что входит | C1: Что не входит | D1: Источник / формула
A2: Выручка | B2: Факт поступлений МДО за месяц | C2: Внутренние переводы и возвраты депозитов | D2: Мега-таблица, вкладка Аккаунты, строка Факт отдела на р/с
A3: Прямые операционные расходы | B3: Зарплаты операционной команды, налоги, ПО, связь, серверы, банк, подрядчики и другие расходы МДО из CF | C3: Разработчики, аллокация ГК, выплаты учредителям, 66 Бит и отдельные проекты разработки | D3: ЖКХ + Забаланс; учет по месяцу начисления; ВКО исключаются
A4: Разработка МДО | B4: Полная стоимость текущей команды разработки, отдельно зафиксированная владельцем модели | C4: 66 Бит и отдельные проектные подрядчики | D4: Отдельный управленческий ввод; в CF зарплаты разработчиков не отражены
A5: Операционные расходы МДО всего | B5: Прямые операционные расходы + разработка МДО | C5: Аллокация ГК и разовые выплаты | D5: E = C + D
A6: Аллокация / услуги ГК | B6: Общие услуги и расходы ГК, распределенные на МДО: HR, юристы, маркетинговые сервисы, АХО и аналогичные услуги | C6: Прямые расходы МДО и команда разработки | D6: Операции CF с признаком распределения / согласованная аллокация
A7: Операционный результат | B7: Результат основной деятельности после прямых OPEX, разработки и аллокации | C7: Выплаты учредителям, 66 Бит и отдельные проектные выплаты | D7: G = B - E - F
A8: Выплаты учредителям | B8: Распределение денежных средств собственникам и связанные комиссии | C8: Операционные расходы | D8: Отдельные операции CF / ручной ввод при отсутствии операции в CF
A9: Выплаты ООО «66 Бит» | B9: Платежи подрядчику по договору разработки | C9: Текущая команда разработки МДО | D9: CF либо отдельный управленческий ввод, если платеж не отражен в CF
A10: Отдельные проекты разработки | B10: Разовые выплаты внешним подрядчикам, например ООО «Бренд Лаборатория» | C10: Городская реклама за колл-центр; текущая команда разработки; 66 Бит | D10: Платежи конкретным юридическим лицам по счетам и назначению платежа
A11: Всего расходов и выплат | B11: Операционные расходы, аллокация, выплаты учредителям и подрядчикам | C11: Внутренние переводы и депозиты | D11: K = E + F + H + I + J
A12: Денежный результат после всех выплат | B12: Выручка минус все отраженные расходы и выплаты | C12: Остаток денег на счете | D12: L = B - K
